Workbook
Name Confidence: Key!$A$15:$A$17
Name EvalScore: Key!$A$22:$A$26
Name RiskRelevant: Key!$A$31:$A$33
Name Typology: Key!$A$6:$A$10

Sheet Contents
F4: Full list of CCRA3 risk and opportunity scores
F7: This spreadsheet summarises all of the magnitude and urgency scores, by UK nation, for each climate change risk and opportunity assessed in the CCRA3 Technical Report. Also shown are the Committee's scores against the criteria used to determine the top eight priority risk areas for action in the next two years, outlined in the CCRA3 Advice Report.
F17: Source: https://www.theccc.org.uk/publication/independent-assessment-of-uk-climate-risk/#supporting-data-charts

Sheet Full scores
D1: Magnitude Score
A2: Risk or Opportunity Descriptor (BOLD = Committee priority risks) | B2: Chapter | C2: Nation | D2: Present Day | E2: 2050, 2° | F2: 2050, 4° | G2: 2080, 2° | H2: 2080, 4° | I2: Adaptation Score | J2: Urgency Score | K2: UK-wide Urgency score for Advice Report | L2: CCC Progress Scores for England (2019)* | M2: CCC Progress Scores for Scotland (2019)* | N2: Key policy opportunities in the next 2 years (UK wide, Committee View)
A3: N1 Risks to terrestrial species and habitats from changing climatic conditions and extreme events, including temperature change, water scarcity, wildfire, flooding, wind, and altered hydrology (including water scarcity, flooding and saline intrusion) | B3: 3 | C3: England | D3: High | E3: High | F3: High | G3: High | H3: High | I3: Partially | J3: More action needed | K3: More action needed | L3: Low (3) | M3: Medium (Amber) | N3: High (Environment and nature recovery policy reform)
B4: 3 | C4: Scotland | D4: High | E4: High | F4: High | G4: High | H4: High | I4: Partially | J4: More action needed
B5: 3 | C5: Wales | D5: High | E5: High | F5: High | G5: High | H5: High | I5: Partially | J5: More action needed
B6: 3 | C6: Northern Ireland | D6: High | E6: High | F6: High | G6: High | H6: High | I6: Partially | J6: More action needed
A7: N2 Risks to terrestrial species and habitats from pests, pathogens and invasive species | B7: 3 | C7: England | D7: Medium | E7: High | F7: High | G7: High | H7: High | I7: Partially | J7: More action needed | K7: More action needed | L7: Low (3) | M7: Medium (Amber) | N7: High (Environment and nature recovery policy reform)
B8: 3 | C8: Scotland | D8: Medium | E8: Medium | F8: Medium | G8: Medium | H8: High | I8: Partially | J8: More action needed
B9: 3 | C9: Wales | D9: Medium | E9: Medium | F9: Medium | G9: Medium | H9: High | I9: Partially | J9: More action needed
B10: 3 | C10: Northern Ireland | D10: Medium | E10: Medium | F10: Medium | G10: Medium | H10: High | I10: Partially | J10: More action needed
A11: N3 Opportunities from new species colonisations in terrestrial habitats | B11: 3 | C11: England | D11: Medium | E11: Medium | F11: Medium | G11: Medium | H11: High | I11: No | J11: Further investigation | K11: Further Investigation | L11: Low (3) | M11: N/A | N11: Low (No key policies looking at opportunities in the next 2 years)
B12: 3 | C12: Scotland | D12: Medium | E12: Medium | F12: Medium | G12: Medium | H12: High | I12: No | J12: Further investigation
B13: 3 | C13: Wales | D13: Medium | E13: Medium | F13: Medium | G13: Medium | H13: High | I13: No | J13: Further investigation
B14: 3 | C14: Northern Ireland | D14: Medium | E14: Medium | F14: Medium | G14: Medium | H14: High | I14: No | J14: Further investigation
A15: N4 Risk to soils from changing climatic conditions, including seasonal aridity and wetness. | B15: 3 | C15: England | D15: Medium | E15: High | F15: High | G15: High | H15: High | I15: Very partially | J15: More action needed | K15: More action needed | L15: N/A | M15: Low (Red) | N15: High (New land management and rural support schemes)
B16: 3 | C16: Scotland | D16: Medium | E16: High | F16: High | G16: High | H16: High | I16: Very partially | J16: More action needed
B17: 3 | C17: Wales | D17: Medium | E17: High | F17: High | G17: High | H17: High | I17: Very partially | J17: More action needed
B18: 3 | C18: Northern Ireland | D18: Medium | E18: High | F18: High | G18: High | H18: High | I18: Very partially | J18: More action needed
A19: N5 Risks and opportunities for natural carbon stores, carbon sequestration and GHG emissions from changing climatic conditions, including temperature change and water scarcity | B19: 3 | C19: England | D19: Medium | E19: High | F19: High | G19: High | H19: High | I19: No | J19: More action needed | K19: More action needed | L19: N/A | M19: Low (Red) | N19: High (Net Zero, new land management and rural support schemes, Environment and nature recovery policy)
B20: 3 | C20: Scotland | D20: Medium | E20: High | F20: High | G20: High | H20: High | I20: No | J20: More action needed
B21: 3 | C21: Wales | D21: Medium | E21: High | F21: High | G21: High | H21: High | I21: No | J21: More action needed
B22: 3 | C22: Northern Ireland | D22: Medium | E22: High | F22: High | G22: High | H22: High | I22: No | J22: More action needed
A23: N6 Risks to and opportunities for agricultural and forestry productivity from extreme events and changing climatic conditions (including temperature change, water scarcity, wildfire, flooding, coastal erosion, wind and saline intrusion). | B23: 3 | C23: England | D23: Medium | E23: High | F23: High | G23: High | H23: High | I23: Very partially | J23: More action needed | K23: More action needed | L23: Low (1) | M23: Low (Red) | N23: High (Net Zero, new land management and rural support schemes, Environment and nature recovery policy)
B24: 3 | C24: Scotland | D24: Medium | E24: High | F24: High | G24: High | H24: High | I24: Very partially | J24: More action needed
B25: 3 | C25: Wales | D25: Medium | E25: High | F25: High | G25: High | H25: High | I25: Very partially | J25: More action needed
B26: 3 | C26: Northern Ireland | D26: Medium | E26: High | F26: High | G26: High | H26: High | I26: No | J26: More action needed
A27: N7 Risks to agriculture from pests, pathogens and invasive species | B27: 3 | C27: England | D27: Medium | E27: High | F27: High | G27: High | H27: High | I27: Partially | J27: More action needed | K27: More action needed | L27: Low (1) | M27: Low (Red) | N27: High (New land management and rural support schemes, naure recovery policy reform)
B28: 3 | C28: Scotland | D28: Medium | E28: High | F28: High | G28: High | H28: High | I28: Partially | J28: More action needed
B29: 3 | C29: Wales | D29: Medium | E29: High | F29: High | G29: High | H29: High | I29: Partially | J29: More action needed
B30: 3 | C30: Northern Ireland | D30: Medium | E30: High | F30: High | G30: High | H30: High | I30: Partially | J30: More action needed
A31: N8 Risks to forestry from pests, pathogens and invasive species | B31: 3 | C31: England | D31: Medium | E31: High | F31: High | G31: High | H31: High | I31: Partially | J31: More action needed | K31: More action needed | L31: Medium (5) | M31: Medium (Amber) | N31: High (New land management and rural support schemes, nature recovery policy reform)
B32: 3 | C32: Scotland | D32: Medium | E32: High | F32: High | G32: High | H32: High | I32: Partially | J32: More action needed
B33: 3 | C33: Wales | D33: Medium | E33: High | F33: High | G33: High | H33: High | I33: Partially | J33: More action needed
B34: 3 | C34: Northern Ireland | D34: Medium | E34: High | F34: High | G34: High | H34: High | I34: Partially | J34: More action needed
A35: N9 Opportunities for agricultural and forestry productivity from new/alternative species becoming suitable. | B35: 3 | C35: England | D35: Medium | E35: High | F35: High | G35: High | H35: High | I35: No | J35: Further investigation | K35: Further Investigation | L35: Low (1) | M35: N/A | N35: Low (No key policies looking at opportunities in the next two years)
B36: 3 | C36: Scotland | D36: Medium | E36: High | F36: High | G36: High | H36: High | I36: No | J36: Further investigation
B37: 3 | C37: Wales | D37: Medium | E37: High | F37: High | G37: High | H37: High | I37: No | J37: Further investigation
B38: 3 | C38: Northern Ireland | D38: Medium | E38: High | F38: High | G38: High | H38: High | I38: No | J38: Further investigation
A39: N10 Risks to aquifers and agricultural land from sea level rise, saltwater intrusion | B39: 3 | C39: England | D39: Low | E39: Low | F39: Low | G39: Low | H39: Unknown | I39: Yes | J39: Further investigation | K39: Further Investigation | L39: N/A | M39: N/A | N39: Low (no key policies in the next two years)
B40: 3 | C40: Scotland | D40: Low | E40: Low | F40: Low | G40: Low | H40: Low | I40: Yes | J40: Watching brief
...

Sheet Contents Page
B2: About this document
B4: This document was produced by RSK ADAS Limited ('ADAS') on behalf of the Climate Change Committee.
B5: Please refer to the report which accompanies this spreadsheet for further information.
B7: Contents
B9: This document has eight tabs which contain the following information:
B11: Tab | C11: Description
B12: Contents Page | C12: Background information and contents of this document.
B13: CCRA3 Risks | C13: Summary table of the CCRA3 risks and content from the Technical Report for 'Benefits of further adaptation action in the next five years'.
B14: CCRA3 actions for NAP3 | C14: Evaluation of the extent to which NAP3 addressed the adaptation actions recommended in CCRA3.
B15: PR23 Recommendations | C15: Outlines the CCC recommendations to Government in the 2023 Progress Report to Parliament and the Government's response to these.
B16: Graphs | C16: Summary visualisations to illustrate evaluation findings.
B17: No. actions per risk | C17: Provides a summary of the number of inferred adaptation actions that were provided in the CCRA3 Technical Report, per risk.
B18: Glossary | C18: Summary of acronyms used within the Government's Response to the CCC Recommendations.
B19: Key | C19: Key to typologies and evaluation scores used in the assessment.
B21: Data sources
B23: The source of data for each column in each tab is listed within the note for each column title.
B25: Summary of data sources used within this document:
B27: Document | C27: Available from:
B28: CCC (2021) Advice to Government - Full Risk Table - Scoring and Priorities | C28: https://www.theccc.org.uk/wp-content/uploads/2021/07/Independent-Assessment-of-UK-Climate-Risk-Advice-to-Government-Full-Risk-Table-Scoring-and-Priorities.xlsx
B29: CCC (2023) Progress Report to Parliament | C29: https://www.theccc.org.uk/publication/progress-in-adapting-to-climate-change-2023-report-to-parliament/
B30: Defra (2023) The Third National Adaptation Programme (NAP3) and the Fourth Strategy for Climate Adaptation Reporting | C30: https://assets.publishing.service.gov.uk/media/64ba74102059dc00125d27a7/The_Third_National_Adaptation_Programme.pdf
B31: Defra (2023) Annex 1: Climate risks and opportunities | C31: https://assets.publishing.service.gov.uk/media/64b52a430ea2cb001315e3b7/NAP3_Annex_1_Climate_risks_and_opportunities.pdf
B32: Defra (2023) Government response to the Climate Change Committee 2023 report to Parliament – progress in adapting to climate change | C32: https://www.gov.uk/government/publications/government-response-to-the-climate-change-committee-2023-adaptation-progress-report/government-response-to-the-climate-change-committee-2023-report-to-parliament-progress-in-adapting-to-climate-change
B33: UK Climate Risk (2021) Independent Assessment (CCRA3) Technical Report | C33: https://www.ukclimaterisk.org/publications/technical-report-ccra3-ia/

Sheet CCRA3 Risks
A1: ID# | B1: Risk or Opportunity Descriptor (BOLD = Committee priority risks) | C1: Committee Priority risk | D1: Chapter | E1: Benefits of further adaptation action in the next five years (CCRA3 section X.X.3) | F1: Indicative costs and benefits of additional adaptation (CCRA3 section X.X.3.1) | G1: Nation | H1: England Magnitude Score Present Day | I1: England Magnitude Score 2050, 2° | J1: England Magnitude Score 2050, 4° | K1: England Magnitude Score 2080, 2° | L1: England Magnitude Score 2080, 4° | M1: England Adaptation Score | N1: England Urgency Score | O1: UK-wide Urgency score for Advice Report | P1: CCC Progress Scores for England (2019)* | Q1: CCC Progress Scores for Scotland (2019)* | R1: Key policy opportunities in the next 2 years (UK wide, Committee View) | S1: Nature | T1: Working land and seas | U1: Food security | V1: Water supply | W1: Energy | X1: Telecommunications & ICT | Y1: Transport | Z1: Towns and Cities | AA1: Buildings | AB1: Health | AC1: Community preparedness and response | AD1: Business | AE1: Finance | AF1: Interdependencies | AG1: Not captured
A2: B01 | B2: B1 Risks to business sites from flooding | C2: No | D2: 6 | E2: Given our assessment above, our view is that there will be significant benefits from further action in the next five years from low-regret actions to improve the evidence base and provide further awareness raising, advice and support to businesses to improve their resilience to flooding. Quantifying risks and impacts is difficult, particularly for individual business sectors, where data is often commercially sensitive. However, Sayers et al. (2020) report that if further adaptation measures are taken, in addition to what is currently planned then the UK-wide expected annual damages for non-residential properties could decrease by up to 21% increase by 2080. Results are calculated under the Enhanced Whole System model. Businesses could also make use of the flood forecasting and warning services provided by the Environment Agency, Natural Resources Wales and SEPA, in conjunction with the Met Office, to plan for and respond to flooding in their areas. In terms of government support, stakeholder engagement indicates that investing in 3D interactive models for commercial properties would be beneficial for data collection. Whilst this will require significant government investment, insurance companies alone are unlikely to bear the upfront costs. It is likely that improving the uptake of property flood protection by businesses will have significant benefits in the next five years, though further data are required to understand this and the current level of uptake specifically in the context of SMEs. | F2: The overall benefits of further investment in flood management for commercial property through the reduction in expected annual damages are estimated by Sayers et al. (2020). This study does not estimate the costs of these measures, and thus does not undertake a cost-benefit analysis, but the literature in general reports high benefit to cost ratios from such investment (Rojas et al., 2013: Ward et al., 2017). There are some low regret activities where Government can act to enhance adaptation in the private sector. The uptake of adaptation measures by businesses is relatively low, with small businesses particularly at risk: only a quarter of businesses with fewer than 10 employees have continuity plans for extreme weather (in GOS and Foresight, 2017). This despite the fact that such plans are a cost-effective adaptation measure: around four-fifths of businesses with continuity plans in place report that the benefits of having a plan exceed the costs of producing one. There is, therefore, a role for raising awareness on climate risks (flood alerts) and providing relevant information and response planning. There is now a reasonable evidence base on the costs and benefits of property resilience and resistance measures for households (Environment Agency, 2015; Wood Plc 2019). These found that a number of flood resilience and resistance measures could be considered no-regret adaptation measures (i.e., a benefit to cost ratio of greater than one in cases where there is a greater than 1% chance of Annual Exceedance Probability, AEP). In general, this literature reports that all measures are more expensive if retrofitted rather than installed in new builds. For resistance measures, the difference between costs of retrofitting vs. incorporating into new builds are more modest. However, the applicability of each of these measures depends on the type of flooding (recurrence and depth), as this alters the relative cost-effectiveness (and benefit to cost ratio). While there is less data on the costs and benefits of similar measures for commercial properties, it is likely that similar findings of low-regret adaptation opportunities apply. There is also some wider literature on the benefits of blue and green infrastructure in alleviating direct and indirect damages from flooding to industry and infrastructure, using the city of Newcastle as a case study (Blue-Green Cities Project, 2016). This assessed the benefits of sustainable urban drainage on water flow, sediment dynamics and flood risk in fluvial systems. Given the residual damage costs even with current flood management policy (Sayers et al., 2020) this is clearly an area where there are benefits of future action, and in many cases these benefits are projected to outweigh the costs. | G2: England | H2: High | I2: High | J2: High | K2: High | L2: High | M2: Partially | N2: More action needed | O2: More action needed | P2: Medium (5) | Q2: Medium (Amber) | R2: Medium (implementation of flood policies) | AD2: Y
A3: B02 | B3: B2 Risks to business locations and infrastructure from coastal change from erosion, flooding and extreme weather events | C3: No | D3: 6 | E3: 6.3.3.1 Additional planned adaptation that would address the adaptation shortfall? (B2) Adaptation actions in the next five years have the potential to enable business opportunities to be created from climate change impacts on the coast, and possibly to avoid further losses. Opportunities exist for coastal businesses from the re-designation of management policy in coastal areas (e.g., from defended to undefended). Depending on the designation, the opportunity exists for businesses to bid for coastal partnership funding to redevelop the coastal area. There is also the potential for business opportunities to emerge from habitat creation, or new approaches to construction to enable communities to ‘live with rising seas’. Coastal properties could also be purchased and repurposed to generate income, e.g., wind farms, temporary holiday lets (Coastal Partnership East, 2019) Overall there is a lack of research and evidence in this area. There is also a business opportunity for new designs/building structures, such as portable beach homes which can be lifted out of harm’s way, providing low impact low risk solutions for future sea-side tourism. Sayers et al. (2020) report that if further adaptation measures are taken, in addition to what is currently planned (see Figure 6.8), then the UK-wide expected annual damages for non-residential properties will increase by 5% in 2050 and increase by 27% by 2080 compared to present day levels of expected damage in the 2°C warming scenario and increase by 27% by 2050 and 58% by 2080 in the 4°C warming scenario. It should be noted however that the Sayers report did not cover coastal erosion and was concluded before the publication of the National Flood and Coastal Erosion Risk Management Strategy (Environment Agency, 2020b) and the Flood and Coastal Erosion Risk Management Strategy Policy Statement (HM Government, 2020). Results are calculated under the Enhanced Whole System model, with results by country for both the 2°C and 4°C warming scenarios presented in Figure 6.9. As can be seen, additional adaptation would significantly decrease expected annual damages to non-residential properties in Scotland and Wales. It is important to note that adaptation solutions do not apply across the board and are context specific. For example, increased coastal protection may work in one community in response to sea level rise, but relocation may be more feasible for a different community. Figure 6.9 Further adaptation: Percentage change in expected annual damages to non-residential properties for scenarios of global warming reaching 2°C and 4°C in the late 21st Century - coastal flooding, direct, £millions (%). Source: Sayers et al. (2020) Some other potential benefits of further adaptation in the next five years include increased transparency about protection levels and limits to avoid false sense of security; public engagement in developing future visions for coastal communities; or investments in community resilience. According to the CCC coastal change report (CCC, 2018), one of the main factors that could aid implementation of more proactive, and cost-effective relocation of coastal properties and assets at risk (i.e., ‘move the risk’), is a change in government policy, associated funding prioritisation and outcome measures. It should be noted that this report was published before the publication of the National Flood and Coastal Erosion Risk Management Strategy (Environment Agency, 2020b) and the Flood and Coastal Erosion Risk Management Strategy Policy Statement (HM Government, 2020). These changes could facilitate the ability to plan and implement the management approaches identified for each of the coastal areas around the UK, particularly those at high risk. More active business engagement with existing resources available for coastal development in ‘at risk’ areas would likely increase adaptation, for example through FCERM partnership funding and Grant-in-Aid support. New guidance was released on the Grant-in-Aid scheme in 2020 to help businesses identify what resources are available for adaptation and what additional funds would need to be secured. Transparency around planned coastal designation changes (from defended to undefended) could support more active adaptation. Providing clearer communication and more transparency should help businesses to avoid a false sense of security and to allow them to plan for future climate risks. Given that the Shoreline Management Plans are non-statutory policy documents, they can only inform wider strategic planning. The Plans also do not consider the full scale of future climate change risks (e.g., high++ scenarios) and do not set out the more radical adaptation responses that could manage those risks. The CO-designing the Assessment of Climate Change costs (COACCH) research report (COACCH, 2019a) notes that the costs of adaptation vary significantly with the level of future climate change, the level of acceptable risk protection and the framework of analysis (protection versus economic efficiency). Recognising and working with uncertainty as part of integrated and sustainable policies requires an iterative and flexible approach that positions coastal change adaptation within a broader integrated coastal-zone management policy framework. For example, new coastal development visions should be fully aligned with climate futures. The COACCH Report, which also includes an analysis of adaptation in the UK, reinforces the message that the most appropriate response to sea-level rise for coastal areas is a combination of adaptation to deal with the inevitable rise and mitigation to limit the long-term rise to a manageable level (COACCH, 2019a) Climate change forms part of a range of risks and uncertainties most industries routinely face. For example, seafood sector adaptations could include much closer science-industry collaboration and engaged research in the short term; and a move towards a more robust and strategic fisheries knowledge base in the medium term (Garrett et al., 2015). More work is needed to identify business opportunities in high-risk coastal areas, including better understanding of funding resources, clearer communication and a realistic appraisal of the risks and opportunities for businesses at the coast. More research is required to understand the costs and benefits of different adaptation responses to loss of coastal locations for businesses and infrastructure. Further analysis is required on how risk will change in the future and how this should inform decisions on a national outcome and strategy for flood risk alleviation. The National Infrastructure Commission (NIC) proposed the adoption or exploration of national minimum standards of resilience (NIC, 2018) though as yet this has not been adopted by government. Defra (2018) indicate that local businesses (potentially with assets at risk) are often an important source of partnership funding for larger schemes. This must be capitalised during stakeholder engagement. Moreover, critical business infrastructure like transport or ports, as well as industry critical business infrastructure such as industrial plants (i.e. chemical and petrochemical plants, oil refineries, gas processing plants) and factories (i.e., food processing facilities, pharmaceutical manufacturing), which are typically located on the coast or on tidal rivers / estuaries out of necessity for process feedstock import and finished product export can be given a level of protected status when it comes to government flood risk management, as suggested by ABP (2016). The Institute of Mechanical Engineers suggests that this infrastructure is vital to national economic prosperity and growth as well as local economies and communities (IMechE 2019). Our view is that for some sectors and some parts of the UK, guidance on appropriate adaptation in the short term has been identified (e.g., fisheries in England and Scotland), however in other parts of the UK, more investigation is needed to identify pathways of action, for example in Northern Ireland. Since CCRA2, the policy environment has changed, creating new opportunities for businesses and creating more adaptation guidance and support in all four of the UK countries. In the longer term, actions relating to the institutional arrangements for adaptation could be considered. For example, governance of fisheries (of both regulated and non-regulated species) could be adapted in the short, medium and long term as there will likely be a need for flexible institutional arrangements to respond to climate change. The finance sector can encourage adaptation by policyholders through incentivisation; Governments and insurers can play a key role by providing further financial incentives for adaptation; for instance, they can set policy premiums at a level that more closely reflects the risk to which individual properties are exposed. However, some elements of coastal change such as erosion are excluded from insurance. If adaptation measures are not implemented, the insurance that currently exists will become more expensive and less available. At present, flood insurance for businesses is being driven by private insurance companies, with low government scope or obligation to pay compensation (Sayers et al., 2020). This issue merits further investigations given lack of consideration in current flooding evidence reports (Sayers et al., 2020). | F3: The overall benefits of further investment in coastal flood management for commercial property – and the reduction in expected annual damages – are shown in Figure 6.8 and 6.9 The Sayers et al. (2020) study does not estimate the costs of these measures, and thus does not undertake a cost-benefit analysis. In general terms, the literature reports that coastal adaptation is an extremely cost-effective response, significantly reducing residual damage costs to very low levels (Hinkel et al., 2014), however, in rural areas, such measures often have benefit-cost ratios lower than one. A new approach to investigating the wider dividends of adaptation and resilience interventions is demonstrated by Roezer et al., 2021 for the case of Felixstowe on the East Coast of England, where increased coastal protection from the new flood defences stimulated new investments in the property sector including the creation of new jobs and a boost to local businesses through increase in visitors, of which the local authority attributed around 50% to the new flood protection scheme. The assessment and retrospective evaluation of additional resilience dividends by the Coastal Partnership East (CPE), a group of local authorities, as part of the monitoring and valuation stage was done to support the business case for similar projects and future interventions. (Roezer et al., 2021). | G3: England | H3: Medium | I3: High | J3: High | K3: High | L3: High | M3: Partially | N3: More action needed | O3: More action needed | P3: Medium (5) | Q3: Medium (Amber) | R3: Medium (New or reviewed coastal policies and implementation of renewed flood policies) | AD3: Y
A4: B03 | B4: B3 Risks to businesses from water scarcity | C4: No | D4: 6 | E4: 6.4.3.1 Additional planned adaptation that would address the adaptation shortfall? (B3) Watkiss et al. (2019) found that there are high benefits (although also high potential costs) of further action to reduce the risk of water scarcity. The costs and benefits do not just fall under the category of businesses but are part of a larger picture of action to reduce demand and increase supply across business, infrastructure, and households, with an aim of protecting and enhancing the natural environment. Currently, there is a lack of incentives for water companies to help reduce commercial water use, and reduction efforts have been left to the retail market, unlike in the domestic sector. Further understanding of sectoral usage is required for this (Ofwat and Environment Agency, 2020). Water UK (2016) has estimated that a ‘twin track’ approach of demand management coupled with appropriate development of new resources and potential transfers is the most suitable strategy for providing drought resilience in the future. They estimated that total costs per annum for all potential future scenarios to maintain resilience at existing levels in England and Wales are between £50 million and £500 million per annum in demand management and new water resource options. If resilience to ‘severe drought’ is adopted, this increases to between £60 million and £600 million and for resilience to extreme drought (beyond the 1 in 100-year event) to between £80 million and £800 million per annum. In England a number of the policy measures that Defra consulted on in 2019 to reduce personal water use, for example, could also help increase business water efficiency and reduce water and energy use. Prime among these is water efficiency labelling of water using products linked to minimum standards for new build and retrofits which would realise significant benefits both for domestic and business water users (Defra, 2019). One idea MOSL (2020) are looking at is to map out their data on business water users and overlay that data set with maps of current or future water stress areas the Environment Agency hold. This would help identify where efforts to reduce business use could be prioritised and what types of businesses/sectors could be targeted. Ideally this can be used to inform next round of water resource plans so a further adaptation action for the next 5 years. High consumption businesses can be incentivized monetarily, for instance through cheaper rates for businesses if they don’t consume in the summer when peak demand is hard to manage. Some of the key business benefits of handling water stewardship effectively include (WWF and M&S, 2017) reduced water related business risk, increased drought preparedness, reduced carbon emissions from supply and heating of water, continuity of supply from sourcing locations for retail businesses, cost savings associated with water efficiency, strong engagement with the local community, and reputational benefits. WWF suggests there will be significant benefits to the UK from taking the following further actions (WWF, 2015): the UK government should share the evidence base, for example the Environment Agency’s water and agriculture monitoring, widely with business and explore opportunities to help businesses identify key hotspots (e.g., showing impacts related to product type). To ensure there is a strong framework for the sustainable management of water WWF suggests more efforts to bring non-compliant farmers in England into compliance and ensuring basic legislation is sufficient to support further achievement of good heath, as defined by the Water Framework Directive. Other suggestions focus on reforming abstraction licensing to ensure environmental needs are met as a function of every licence and that abstraction charges encourage efficient use; and continuing investment in the Catchment Based Approach including by exploring ways to encourage private sector support and funding (WWF 2015). Stakeholder discussions as part of the UKCCRA3 stakeholder engagement indicate that a consistent methodology for measuring & reporting water use for products (water foot printing) is to be encouraged. There would be benefits to looking at whole life cycle approach to measuring water usage and make sure embedded water is fully taken into account in such reporting. The long-term trends and pinch point analysis would provide useful tools for industry and Government to show where to focus efforts for either improved water efficiency of business or increased resilience of supply. The retail market could help to create incentives for businesses to become more water efficient but has so far only had a limited impact. The opening of the retail market for water offers multiple benefits for businesses but the potential effect on water efficiency is uncertain. The CEO Water Mandate’s Corporate Water Disclosure Guidelines offer a common approach to disclosure. They put forward metrics that can begin to harmonize practice and also provide guidance for defining what to report. These Guidelines have the potential to drive convergence and harmonization with respect to how companies report their water management practices while helping to minimize reporting burdens, thus allowing companies to allocate more time and resources to actively manage water. The list of endorsing companies as well as reports on their progress can be found online and are updated regularly (CEO Water Mandate, 2014). | F4: As highlighted above, there are studies which have considered the overall costs and benefits of national level action to reduce the risk of water scarcity. There are also a complementary set of demand side measures that can be introduced by businesses, many of which are no-regret and low-regret. As a general rule of thumb, reductions of 30% in water bills are usually achievable at little or no cost for sites that have not previously tried to save water, and as much as 50%, or more, if projects with capital investment payback periods of up to two years are included (WRAP, 2005). There are detailed cost-effectiveness assessments of measures for industrial sites, with indications of costs and payback periods. However, as highlighted above, there remain important barriers to address to encourage the uptake of such measures, which includes a role for government to raise awareness and create appropriate incentives. There is a strong case for Governments to consider adopting consistent national minimum levels of resilience, recognizing that there are significant issues to address, including inter-regional and inter-generational fairness. The investment needed to increase resilience appears relatively modest compared with the cost of drought. A twin-track approach that includes supply enhancement, with associated transfers, as well as demand management, is the most appropriate strategic mix for the future. There is a case for a national level adaptive plan that supports ongoing water company plans and balances risks against opportunities to defer costs. See also Chapter 4 (Jaroszweski, Wood and Chapman, 2021) and Chapter 5 (Kovats and Brisley, 2021). | G4: England | H4: Low | I4: Medium | J4: Medium | K4: Medium | L4: High | M4: Partially | N4: Further investigation | O4: Further Investigation | P4: Medium (5) | Q4: High (Green) | R4: Low (no key policies in the next two years) | AD4: Y
A5: B04 | B5: B4 Risks to finance, investment and insurance including access to capital for businesses | C5: No | D5: 6 | E5: 6.5.3.1 Additional planned adaptation that would address the adaptation shortfall? (B4) There have been significant shifts in assessing, disclosing and analysing climate risks and more is expected in light of expected shifts from voluntary to mandatory action driven by regulators. However, translating this increased risk knowledge into action and drawing conclusions is equally important, and the extent to which companies will successfully do this remains unclear. While it is clear that the extent of physical risks is currently low and expected to become significant in the longer-term there are clear dangers in considering physical risks ‘as under control’: lock-ins for example in terms of real-estate investment but also lack of insurance uptake, particularly on business continuity. Since CCRA2, changes have mainly been made in climate risk regulation and reporting as opposed to changing capital flows. Moreover, given the tightening climate policy landscape, there are significant lock-in effects if there is no substantial redirection of financial flows. Whilst banking and insurance sectors have effectively responded to current extreme weather events, the increase in magnitude and frequency of impacts in the future means the likelihood of “unhedgeable risk” is higher – straining the insurance sector. Given that financial risks are still not integrated within firm operating models or in financial markets as a whole, there are still significant systemic risks (Mandel et al, 2020). Whilst companies have started adopting TCFD recommendations, identifying climate risks is only the first step. TCFD’s most recent status update report acknowledges that there needs to be a better understanding of how disclosing climate-related financial information is changing corporate strategies on adaptation, and how investors are using the disclosed information to inform their decisions (Power et.al. 2020; TCFD, 2020). CISL (2019) recommends early action in addressing risks to accessing finance and investment is predicted to lead to higher economic growth rates and returns over the long run when compared to scenarios of inaction. Moreover, further investment is required to scale-up pre-existing resilience solutions and technologies (NDF, 2020). The following are a number of key areas that could be addressed in the next five years: ● Requirements imposed on banks and insurers: Based on Pillar 2 of the supervision of institutions’ risk management, regulators could prescribe additional capital on a case-by-case basis, for instance if a financial institution does not adequately monitor and manage climate-related risks. This would first require new expectations to be set in this regard (BIS, 2020). Further action is required by banks in order to meet Bank of England stress testing requirements. Currently there is very little data and organisational capacity to collect information in the aftermath of disasters (e.g. collection strategies after a flood) (Deloitte, 2020). Banks require data (e.g. location of collateral, exposure to carbon intensive industries etc.) in order to better respond to physical and transition risk. For instance, green vs brown exposure and funding of carbon intensive industries is not being considered (Deloitte, 2020). In scenario analysis, the banking sector needs to adopt and consider much longer timelines than it is used to at present (Deloitte, 2020). ● Broadening scope of existing regulations: The current review of climate stress testing by the Bank of England’s PRA (Bank of England, 2019) provides an opportunity to broaden the scope, identify limitations and important constraints, and support companies in their internal interpretation of scenario analysis results. Whilst the stress-testing is intermittently paused due to COVID-19 (IMF, 2020), this could be a step towards encouraging more scenario-based analysis among financial institutions on a regular basis. In the future, regulators could make it mandatory for financial institutions to stress-test their portfolios against a common set of scenarios. (UNEP-FI / Vivid 2019). Mandatory disclosure is also called for by the IMF (2020). Stakeholder engagement suggested there is insurers support for this, with mandatory disclosure of methodologies and impact recommended. ● Insurability: Given rising uncertainty, Mckinsey (2020) recommend risk-sharing agreements between private and public financial institutions, similar to that seen in flood insurance, in order to meet financing gaps. Given that Flood Re is only available to non-businesses, there should be increased incentives for resilience to businesses. This also directly relates to uptake of insurance. Whilst there is an increase in the uptake of climate related insurance products, products need to be more streamlined, made cost-effective and user-friendly to promote further business uptake (Marsh & McLennan Companies 2018). Insurance can be used to incentivise risk-reducing behaviour, for example by rewarding adaptation measures like hardening of physical assets (Mckinsey, 2020). As highlighted in section 7.10 of Chapter 7 (Challinor and Benton, 2021), this uptake in insurance from the UK’s expertise within re-insurance companies and catastrophe risk modelling organisations is an opportunity for the UK insurance market to grow. ● Disclosing and reporting: Further standardisation and clarification on scenario analysis models are required so comparisons can be made. Moreover, inclusion of additional asset classes will make these models more useful for investors (Mercer, 2019). Standardisation can occur through investor collaboration facilitated by government-led initiatives (UNEP-FI, 2019). Scenario analyses currently do not cover the entire value-chain of businesses and further integration is required between transition and physical risks as well as the link between micro and macroeconomic impacts (UNEP-FI, 2019). Further developments of dashboards and monitoring mechanisms are required to capture “investors and markets channelling finance to climate solutions” and change in financial flows are a response to climate risk (CPI, 2019). Additionally, more bottom-up information, such as KPIs from businesses, need to be incorporated in scenario analyses which have predominantly been top-down. A push for disclosure of granular, asset level data is required from businesses for scenario analysis to be successful (UNEP-FI, 2019). ● Financial and physical risk metrics: It is important to recognise the interplay of financial metrics and physical risk metrics: for example, the credit risk of a bank from increasing physical risk can be low if it does not lend to companies in high-risk areas. Finity (2019) show it is important to distinguish between risk to individual financial companies versus wider financial implications. Unless physical risk is being reduced through more adaptation investment and action, those damages will occur and have financial implications. ● Incorporating risk reduction and data into insurance requirements: One proposed solution relating to the short-term valuation cycle issue is that policymakers and insurers could incorporate risk reduction and adaptation measures into insurance requirements (CISL, 2019). Other options include making sure risk data is populated across a wide range of sectors and groups, including a focus both on the current symptoms and problems and the underlying causes incorporated into day-to-day decision-making. Surminski (2017) showed that it is essential to first address the use of data and transparency around risk levels. This foundational trust and understanding is needed to reduce the risk of the private sector withdrawing altogether from the flood insurance space or consumers not being able or willing to pay high premiums (Surminski, 2017). ● Financing adaptation: Where funding pools exist, like bond markets, better education is required to match counterparties (Marsh & McLennan Companies 2018). Further research is required in the area of new products, such as resilience bonds, which would use premium discounts for long-term planning, such as investment in sustainable infrastructure, in the catastrophe bond market. Synergies between climate financing and risk management strategies in the banking and insurance sector must be further explored (Marsh & McLennan Companies 2018). ● More collaboration between different parts of the financial system: Capital providers to investors and lenders will likely want to understand how such location decisions, intermediated by insurance availability (discussed above) and adaptation action (discussed below), are taking account of the physical risks of climate change. To the extent that investors and lenders do alter location decisions, it is projected to be much less disruptive to the real economy if this happens over a long period of time rather than as an abrupt response to one or a series of particular events (CISL, 2019). However, investors and lenders, combined with policymakers, may find it easier to take a longer-term perspective. They could work in concert with insurers to encourage the uptake of adaptation measures, for instance, by making both loans and insurance contingent on the installation of relevant adaptation measures (CISL, 2019). This is in line with UNEP-FI (2018) who encourage improved collaboration between banks, borrowers, governments and the insurance industry, and would increase the quality of forward-looking disclosures. | F5: It is difficult to estimate the potential costs and benefits of adaptation. However, what is clear is that the potential risks to the financial markets from climate change are extremely large, and because of the role of UK financial services, very large for the UK. EIU (2015) estimated the value at risk, as a result of climate change, to the total global stock of manageable assets (currently $143 trillion) as $4.2 trillion (mean expected losses, discounted in present value terms) between now and the end of the century, and still half this even under a pathway to 2°C global warming by 2100. | G5: England | H5: Medium | I5: Medium | J5: High | K5: Medium | L5: High | M5: Partially | N5: Sustain current action | O5: Sustain current action | P5: Medium (5) | Q5: N/A | R5: High (TCFD reporting, focus on finance for COP26) | AE5: Y
A6: B05 | B6: B5 Risks to business from reduced employee productivity due to infrastructure disruption and higher temperatures in working environments | C6: Yes | D6: 6 | E6: 6.6.3.1 Additional planned adaptation that would address the adaptation shortfall? (B5) The CCRA2 Evidence Report (Surminski et al., 2016) outlined a need to further research and understanding of the key interdependencies between business and infrastructure, the types of employment at greatest risk and the effectiveness of planned or autonomous adaptation. Collecting business continuity information on productivity and extreme weather is critical to understanding this risk better. Adaptation reporting could help to increase uptake and encourage businesses to prioritise this risk, but a requirement would be needed to include productivity risks in reports, which is challenging given the current voluntary approach to reporting adopted by the UK Government. Very few studies have looked at either the risk or adaptation underway in the UK, suggesting further investigation is required across the UK to better quantify both the scale of the problem, and the benefits of implementing measures to address it both in current and future climates. In particular, evidence for future risk from reduced employee productivity is limited. 6.6.3.2 Indicative costs and benefits of further adaptation action (B5) There is some information on various adaptation options to reduce heat in commercial buildings and also linkages to the information available for domestic buildings (see the discussion of low and no-regret options for risk H1, Chapter 5: Kovats and Brisley, 2021). Day et al. (2019) assessed 17 adaptation measures (drawn from a longer list of over 30), including both solutions for indoor and outdoor work, to address higher base temperatures as well short-term temperature peaks. The authors estimated the ‘potential scale of impact’ as well as the ‘feasibility’ of the measures. This also includes analysis of which actions can be taken forward by the private sector, by government and by individuals. The study also considers the economic costs of each adaptation measure including direct financial costs of implementing the measure, and a range of ‘indirect’ costs. Costa et al. (2016) also estimated averted losses from alternative adaptation measures for three case study cities (Antwerp, Bilbao, and London) for a warm year at the end of the century (2081-2100). These studies identify a range of low and no-regret adaptation actions. Some opportunities for labour productivity adaptation are identified such as transition to new ways of working (remote working, flexible working) and low carbon and energy efficiency buildings to maintain employee productivity (ILO, 2019, Day et al., 2019). These behavioural changes have been tested and employed by various businesses with the onset of the COVID-19 pandemic, but longer-term behavioural change is yet to be seen. Moreover, there are occupational and sectoral divergences in the uptake of new ways of working, with some professions lending themselves better to flexible working than others. Increasing collaboration and strengthening governance in this space may also deliver benefits in the next five years. Better collaboration between business, building owners, government and infrastructure operators could help facilitate adaptation. These efforts could replicate the engagement and collaborations seen in the flooding space and be linked to net-zero initiatives, recognizing that heat poses challenges for reaching net-zero. With regards to nature-based solutions as a potential adaptation response to extreme heat, there is emerging literature estimating the climate benefits of urban natural capital at the UK scale (Eftec et al., 2018). This valuation methodology provides estimates of temperature reduction in city areas and benefits, which feed into the Natural Capital Accounts by ONS (ONS 2018). Although experimental in nature, these estimates give a sense of the scale of benefits (particularly in terms of avoided loss of productivity) and how these might rise over time with an increasing frequency of ‘hot’ days. For instance, in 2017, the annual benefits of cooling from green and blue space in urban areas was estimated at £244m, with London dominating the benefits (reflecting the climate of London, the scale of its economy and the unusually large area of green space for such a big city). The ONS 2018 assessment uses analysis from Eftec (Defra, 2018a) and is based on Costa et al.’s (2016). However, increasing the area of large natural spaces in urban areas, in response to rising climate risks, appears challenging, not least because of the opportunity cost of land. Initiatives led by the private sector such as ‘Living roofs and walls – from policy to practice’ aim to address these issues. | F6: N/A | G6: England | H6: Low | I6: Medium | J6: Medium | K6: Medium | L6: High | M6: Partially | N6: Further investigation | O6: Further Investigation | P6: Low (2) | Q6: Medium (Amber) | R6: High (Reviews of building regulations and planning, Net Zero) | AD6: Y
A7: B06 | B7: B6 Risks to business from disruption to supply chains and distribution networks | C7: Yes | D7: 6 | E7: 6.7.3.1 Additional planned adaptation that would address the adaptation shortfall? (B6) The majority of further actions involve capacity building, institutional changes, or the development of new strategies, technologies or ways of working, which will take time to develop, test and implement. Therefore, there is a benefit to putting these in place within the next five years even where the climate-related risks are not immediate. Indeed, the BCI recommends an offensive rather than a defensive approach (Marsh & McLennan Companies 2018), while McKinsey (2020) finds significant potential for many industries to adapt in the next decade. For example, in the case of rare earth metals they estimated that 50-80% of risk could be eliminated if adaptation measures were implemented (McKinsey 2020). Furthermore, many of the actions can be seen as ‘no-regrets’ options business continuity planning that builds resilience in supply chains or improves the quality of business relationships offers immediate benefits. Strategies that businesses could take to further build resilience include: ● Product diversification or geographical diversifying (WWF, 2018). ● Scenario analysis to ensure plans are robust under different plausible outcomes by explicitly defining and separating external scenarios from internal plans (Marsh & McLennan Companies, 2018). ● Ensuring risks are incorporated into risk registers and management programmes so that optimal resources and opportunities to improve corporate performance and earnings can be identified (BCI, 2018a). ● Intensification in the use of storage facilities (COACCH, 2019). ● More ‘bridging’ actions, that is, inclusion of supply chain partners in risk assessments, planning and communications (Crisis Control, 2017). Given the post-EU exit uncertainty due to changing supply chains Tim et al. (2019) recommend more investment in the agricultural systems of source countries in order to minimise climate risk. And the World Business Council for Sustainable Development (Land workers' Alliance, 2019) recommends adopting a circular model for resilience, with shocks and stressors in the food, agriculture and forestry sector, being met with adaptation response and transformation of existing business models and supply chains. ● Making more use of technology to improve traceability mechanisms (YGCP, 2020) and to predict, monitor, record, measure or report supply chain risks and communicate with suppliers. For example, using automated communication and notification systems, BCM platforms, incident management platforms or social media monitoring (favoured by SMEs) (BCI, 2018b; BCI, 2019a). ● Expanding firm level insurance coverage of physical risks to supply chains, including by use of new products such as non-damage supply chain insurance plans and parametric insurance (for example, with pay-outs based on a drought duration index or rainfall data rather than losses) or captive insurance solutions. The latter can improve climate resilience by strategically funding risk exposures, preparing for a worst-case scenario in the face of increasing frequencies and by accessing reinsurance markets and alternative capital markets to fund less predictable risks (Marsh & McLennan Companies, 2018; BCI, 2019a). There are roles for both the public and private sector in driving resilience through supporting or/ incentivising their own supply chains to implement adaptation measures by: ● Requiring physical risk disclosures and setting contractual arrangements that take adaptation into account (UNEP-FI and Acclimatise, 2018). ● Using resilience criteria with choosing suppliers as part of procurement processes (Crisis Control, 2017). For public sector procurement, the Public Services (Social Value) Act provides a potential tool by requiring commissioners of public services to think about how they can also secure wider social, economic and environmental benefits. (Source: CCRA3 Stakeholder Event, February 2020) ● Helping suppliers reduce their own risks (Crisis Control, 2017). For example, the water stewardship approach provides companies with a means of committing resource and using influence to support good water practices in areas of weak governance. ● Promoting business continuity, with a particular focus on strategies that achieve multiple goals including resilience and sustainability for which there may be market failures. For example, distributed manufacturing, seasonal produce and local sourcing have a role to play in achieving both sustainability and resilience goals (Colwill et al., 2016). There is also a role for government in capacity building and setting the right institutional environment (COACCH, 2019), such as by: ● Promoting the establishment of binding supply chain due diligence legislation on a national level while ensuring international alignment (YGCP, 2020). ● Promoting the coherent use and development of modern traceability technology, namely blockchain (YGCP, 2020). ● Supporting improved climate and location-based information and integration with other types of information (UNEP-FI and Acclimatise, 2018). Taking into account all three steps of the urgency assessment we conclude that more action is needed, but with a low certainty in the evidence, which is skewed towards larger companies, the food sector and self-reporting. The reliance on overseas markets means UK supply chains are exposed to climate impacts abroad with exposure increasing due to climate change. While some action has been taken by businesses and others on supply chain resilience and there are opportunities from advances in technologies, there are many barriers to adaptation. It is unclear how effective current and planned actions will be in managing climate or weather-related disruption specifically. The COVID-19 crisis may lead to companies and entire industries rethinking their global supply chain model. This presents an opportunity for step change in government action to facilitate this and achieve multiple benefits. This is applicable across all DAs, but more work is needed to understand regional differences. The evidence base is strongest for England, followed by Scotland, with less for NI and Wales. | F7: There are some aspects of climate change risks and responses that have been quantified for food supply chain resilience. Even here, however, there is little information on the associated costs and benefits (in aggregate), as identified by recent review of food supply chains and adaptation (Watkiss et al., 2019), though it did identify potential adaptation measures and their potential (qualitative) benefits and costs, indicating net beneficial further actions exist. | G7: England | H7: Medium | I7: Unknown | J7: Unknown | K7: Unknown | L7: Unknown | M7: Partially | N7: More action needed | O7: More action needed | P7: Low (2) | Q7: Medium (Amber) | R7: High (TCFD reporting, possible increased focus on supply chain resilience post-Covid) | U7: Y | AD7: Y
